<?xml version='1.0'?>
<!--
  Gazebo ROS differential drive plugin

  Try sending commands:

    ros2 topic pub /khepera_IV/cmd_vel geometry_msgs/Twist '{linear: {x: 0.05}}' -1

    ros2 topic pub /khepera_IV/cmd_vel geometry_msgs/Twist '{angular: {z: 0.1}}' -1

  Try listening to odometry:

    ros2 topic echo /demo/odom

  Try listening to TF:

    ros2 run tf2_ros tf2_echo odom chassis

    ros2 run tf2_ros tf2_echo chassis right_wheel

    ros2 run tf2_ros tf2_echo chassis left_wheel
-->
<sdf version='1.6'>
  <model name='Khepera_IV'>
    <static>false</static>
    <pose>0 0 0 0 -0 0</pose>

    <link name='chassis'>
      <pose>0 0 0.0 0 -0 0</pose>
      <inertial>
        <mass>0.5</mass>
        <inertia>
          <ixx>0.0007365</ixx>
          <ixy>0</ixy>
          <ixz>0</ixz>
          <iyy>0.0007365</iyy>
          <iyz>0</iyz>
          <izz>0.001239</izz>
        </inertia>
      </inertial>

      <visual name='visual'>
        <geometry>
          <mesh>
            <uri>model://khepera_IV/Empty_robot.dae</uri>
            <scale>1 1 1</scale>
          </mesh>
        </geometry>
      </visual>
      <collision name='collision'>
        <geometry>
          <mesh>
            <uri>model://khepera_IV/Empty_robot.dae</uri>
            <scale>1 1 1</scale>
          </mesh>
        </geometry>
      </collision>
    </link>

    <link name='left_wheel'>
      <pose>0 0.0527 0.021 -1.57070 0 0</pose>
      <inertial>
        <mass>0.02</mass>
        <inertia>
          <ixx>0.000003</ixx>
          <ixy>0</ixy>
          <ixz>0</ixz>
          <iyy>0.000003</iyy>
          <iyz>0</iyz>
          <izz>0.000003</izz>
        </inertia>
      </inertial>
      <visual name='visual'>
        <geometry>
          <mesh>
            <uri>model://khepera_IV/wheel.dae</uri>
            <scale>1 1 1</scale>
          </mesh>
        </geometry>
      </visual>
      <collision name='collision'>
        <geometry>
          <mesh>
            <uri>model://khepera_IV/wheel.dae</uri>
            <scale>1 1 1</scale>
          </mesh>
        </geometry>
        <surface>
          <friction>
            <ode>
              <mu>1</mu>
              <mu2>1</mu2>
              <slip1>0</slip1>
              <slip2>0</slip2>
            </ode>
          </friction>
          <contact>
            <ode>
              <soft_cfm>0</soft_cfm>
              <soft_erp>0.2</soft_erp>
              <kp>1e+13</kp>
              <kd>1</kd>
              <max_vel>0.01</max_vel>
              <min_depth>0.01</min_depth>
            </ode>
          </contact>
        </surface>
      </collision>
    </link>

    <link name='right_wheel'>
      <pose>0 -0.0527 0.021 -1.5707 0 0</pose>
      <inertial>
        <mass>0.02</mass>
        <inertia>
          <ixx>0.000003</ixx>
          <ixy>0</ixy>
          <ixz>0</ixz>
          <iyy>0.000003</iyy>
          <iyz>0</iyz>
          <izz>0.000003</izz>
        </inertia>
      </inertial>
      <visual name='visual'>
        <geometry>
          <mesh>
            <uri>model://khepera_IV/wheel.dae</uri>
            <scale>1 1 1</scale>
          </mesh>
        </geometry>
      </visual>
      <collision name='collision'>
        <geometry>
          <mesh>
            <uri>model://khepera_IV/wheel.dae</uri>
            <scale>1 1 1</scale>
          </mesh>
        </geometry>
        <surface>
          <friction>
            <ode>
              <mu>1</mu>
              <mu2>1</mu2>
              <slip1>0</slip1>
              <slip2>0</slip2>
            </ode>
          </friction>
          <contact>
            <ode>
              <soft_cfm>0</soft_cfm>
              <soft_erp>0.2</soft_erp>
              <kp>1e+13</kp>
              <kd>1</kd>
              <max_vel>0.01</max_vel>
              <min_depth>0.01</min_depth>
            </ode>
          </contact>
        </surface>
      </collision>
    </link>

    <link name='front_caster'>
      <pose>0.05 0 0.006614 0 -0 0</pose>
      <visual name='visual'>
        <geometry>
          <mesh>
            <uri>model://khepera_IV/caster.dae</uri>
            <scale>1 1 1</scale>
          </mesh>
        </geometry>
      </visual>
      <collision name='collision'>
        <geometry>
          <mesh>
            <uri>model://khepera_IV/caster.dae</uri>
            <scale>1 1 1</scale>
          </mesh>
        </geometry>
      </collision>
    </link>

    <link name='back_caster'>
      <pose>-0.05 0 0.006614 0 -0 0</pose>
      <visual name='visual'>
        <geometry>
          <mesh>
            <uri>model://khepera_IV/caster.dae</uri>
            <scale>1 1 1</scale>
          </mesh>
        </geometry>
      </visual>
      <collision name='collision'>
        <geometry>
          <mesh>
            <uri>model://khepera_IV/caster.dae</uri>
            <scale>1 1 1</scale>
          </mesh>
        </geometry>
      </collision>
    </link>

    <joint name='left_wheel_joint' type='revolute'>
      <parent>chassis</parent>
      <child>left_wheel</child>
      <axis>
        <xyz>0 0 1</xyz>
        <limit>
          <lower>-1.79769e+308</lower>
          <upper>1.79769e+308</upper>
        </limit>
      </axis>
    </joint>

    <joint name='right_wheel_joint' type='revolute'>
      <parent>chassis</parent>
      <child>right_wheel</child>
      <axis>
        <xyz>0 0 1</xyz>
        <limit>
          <lower>-1.79769e+308</lower>
          <upper>1.79769e+308</upper>
        </limit>
      </axis>
    </joint>

    <joint name='front_caster_wheel' type='ball'>
      <parent>chassis</parent>
      <child>front_caster</child>
    </joint>

    <joint name='back_caster_wheel' type='ball'>
      <parent>chassis</parent>
      <child>back_caster</child>
    </joint>

    <plugin name='diff_drive' filename='libgazebo_ros_diff_drive.so'>

      <ros>
        <namespace>/khepera_IV</namespace>
        <remapping>cmd_vel:=cmd_vel</remapping>
        <remapping>odom:=ground_truth</remapping>
      </ros>

      <!-- wheels -->
      <left_joint>left_wheel_joint</left_joint>
      <right_joint>right_wheel_joint</right_joint>

      <!-- kinematics -->
      <wheel_separation>0.1054</wheel_separation>
      <wheel_diameter>0.021</wheel_diameter>

      <!-- limits -->
      <max_wheel_torque>20</max_wheel_torque>
      <max_wheel_acceleration>1.0</max_wheel_acceleration>

      <!-- output -->
      <publish_odom>true</publish_odom>
      <publish_odom_tf>true</publish_odom_tf>
      <publish_wheel_tf>true</publish_wheel_tf>

      <odometry_frame>odom_demo</odometry_frame>
      <robot_base_frame>chassis</robot_base_frame>
      <odometry_source>world</odometry_source>

    </plugin>

  </model>

</sdf>
