<?xml version="1.0" ?>
<sdf version='1.7'>
  <world name='default'>
    <light name='sun' type='directional'>
      <cast_shadows>1</cast_shadows>
      <pose>0 0 10 0 -0 0</pose>
      <diffuse>0.8 0.8 0.8 1</diffuse>
      <specular>0.2 0.2 0.2 1</specular>
      <attenuation>
        <range>1000</range>
        <constant>0.9</constant>
        <linear>0.01</linear>
        <quadratic>0.001</quadratic>
      </attenuation>
      <direction>-0.5 0.1 -0.9</direction>
      <spot>
        <inner_angle>0</inner_angle>
        <outer_angle>0</outer_angle>
        <falloff>0</falloff>
      </spot>
    </light>
    <model name='ground_plane'>
      <static>1</static>
      <link name='link'>
        <collision name='collision'>
          <geometry>
            <plane>
              <normal>0 0 1</normal>
              <size>100 100</size>
            </plane>
          </geometry>
          <surface>
            <friction>
              <ode>
                <mu>100</mu>
                <mu2>50</mu2>
              </ode>
              <torsional>
                <ode/>
              </torsional>
            </friction>
            <contact>
              <ode/>
            </contact>
            <bounce/>
          </surface>
          <max_contacts>10</max_contacts>
        </collision>
        <visual name='visual'>
          <cast_shadows>0</cast_shadows>
          <geometry>
            <plane>
              <normal>0 0 1</normal>
              <size>100 100</size>
            </plane>
          </geometry>
          <material>
            <script>
              <uri>file://media/materials/scripts/gazebo.material</uri>
              <name>Gazebo/Grey</name>
            </script>
          </material>
        </visual>
        <self_collide>0</self_collide>
        <enable_wind>0</enable_wind>
        <kinematic>0</kinematic>
      </link>
    </model>
    <gravity>0 0 -9.8</gravity>
    <magnetic_field>6e-06 2.3e-05 -4.2e-05</magnetic_field>
    <atmosphere type='adiabatic'/>
    <physics type='ode'>
      <max_step_size>0.001</max_step_size>
      <real_time_factor>1</real_time_factor>
      <real_time_update_rate>1000</real_time_update_rate>
    </physics>
    <scene>
      <ambient>0.4 0.4 0.4 1</ambient>
      <background>0.7 0.7 0.7 1</background>
      <shadows>1</shadows>
    </scene>
    <wind/>
    <spherical_coordinates>
      <surface_model>EARTH_WGS84</surface_model>
      <latitude_deg>0</latitude_deg>
      <longitude_deg>0</longitude_deg>
      <elevation>0</elevation>
      <heading_deg>0</heading_deg>
    </spherical_coordinates>
    <model name='RoboticLab'>
      <pose>1.46452 -0.521669 0 0 -0 0</pose>
      <link name='Lab'>
        <pose>0 0 0 0 -0 0</pose>
        <visual name='visual'>
          <geometry>
            <mesh>
              <uri>model://RoboticLab/files/RoboticPark.dae</uri>
              <scale>1 1 1</scale>
            </mesh>
          </geometry>
        </visual>
        <collision name='collision'>
          <geometry>
            <mesh>
              <uri>model://RoboticLab/files/RoboticPark.dae</uri>
              <scale>1 1 1</scale>
            </mesh>
          </geometry>
          <max_contacts>10</max_contacts>
          <surface>
            <contact>
              <ode/>
            </contact>
            <bounce/>
            <friction>
              <torsional>
                <ode/>
              </torsional>
              <ode/>
            </friction>
          </surface>
        </collision>
        <self_collide>0</self_collide>
        <enable_wind>0</enable_wind>
        <kinematic>0</kinematic>
      </link>
      <static>1</static>
    </model>
    <state world_name='default'>
      <sim_time>115 45000000</sim_time>
      <real_time>50 846344714</real_time>
      <wall_time>1654344029 381217101</wall_time>
      <iterations>50200</iterations>
      <model name='Khepera_IV'>
        <pose>0.000175 -0.000373 0.02491 0.000144 -0.007613 0.000478</pose>
        <scale>1 1 1</scale>
        <link name='back_caster'>
          <pose>-0.049874 -0.000398 0.031142 0.028186 -0.007371 0.061914</pose>
          <velocity>-0.000798 -0.000299 -0.003064 0.001 -0.001041 -5e-06</velocity>
          <acceleration>0.006599 0.060527 0.595942 0 -0 0</acceleration>
          <wrench>0.006599 0.060527 0.595942 0 -0 0</wrench>
        </link>
        <link name='chassis'>
          <pose>0.000175 -0.000373 0.02491 0.000144 -0.007613 0.000478</pose>
          <velocity>-0.000274 -0.000169 0.001148 0.002412 -0.08374 0.002242</velocity>
          <acceleration>0.007783 -0.008267 0.55642 2.06594 0.232292 -1.66153</acceleration>
          <wrench>0.004203 -0.004464 0.300467 0 -0 0</wrench>
        </link>
        <link name='front_caster'>
          <pose>0.050123 -0.00035 0.031902 2.04647 -0.126368 -0.324274</pose>
          <velocity>-0.000864 -7.3e-05 0.00531 -0.103255 0.01794 2e-05</velocity>
          <acceleration>0.004723 -0.105684 0.595885 0 -0 0</acceleration>
          <wrench>0.004723 -0.105684 0.595885 0 -0 0</wrench>
        </link>
        <link name='left_wheel'>
          <pose>-1e-05 0.052323 0.04594 -1.57066 0.031305 0.00048</pose>
          <velocity>-0.001779 -0.000174 0.001528 0.009045 -0.084306 0.004335</velocity>
          <acceleration>0.508233 -0.045987 0.085546 2.59709 0.282558 0.697328</acceleration>
          <wrench>0.010165 -0.00092 0.001711 0 -0 0</wrench>
        </link>
        <link name='right_wheel'>
          <pose>4e-05 -0.053076 0.045924 -1.57042 -0.19686 0.00041</pose>
          <velocity>-0.002025 -0.000184 0.001338 0.008132 -0.097372 0.003748</velocity>
          <acceleration>-0.017959 -0.044336 -0.117518 2.19968 -0.746947 -1.95208</acceleration>
          <wrench>-0.000359 -0.000887 -0.00235 0 -0 0</wrench>
        </link>
      </model>
      <model name='RoboticLab'>
        <pose>0 0 0 0 -0 0</pose>
        <scale>1 1 1</scale>
        <link name='Lab'>
          <pose>0 0 0 0 -0 0</pose>
          <velocity>0 0 0 0 -0 0</velocity>
          <acceleration>0 0 0 0 -0 0</acceleration>
          <wrench>0 0 0 0 -0 0</wrench>
        </link>
      </model>
      <model name='ground_plane'>
        <pose>0 0 0 0 -0 0</pose>
        <scale>1 1 1</scale>
        <link name='link'>
          <pose>0 0 0 0 -0 0</pose>
          <velocity>0 0 0 0 -0 0</velocity>
          <acceleration>0 0 0 0 -0 0</acceleration>
          <wrench>0 0 0 0 -0 0</wrench>
        </link>
      </model>
      <light name='sun'>
        <pose>0 0 10 0 -0 0</pose>
      </light>
    </state>
    <gui fullscreen='0'>
      <camera name='user_camera'>
        <pose>2.72376 0.254332 2.0504 -0 0.599643 -3.11899</pose>
        <view_controller>orbit</view_controller>
        <projection_type>perspective</projection_type>
      </camera>
    </gui>
    <model name='Khepera_IV'>
      <pose>-0.051702 -0.017828 0 0 -0 0</pose>
      <link name='chassis'>
        <pose>0 0 0 0 -0 0</pose>
        <inertial>
          <mass>0.54</mass>
          <inertia>
            <ixx>0.002646</ixx>
            <ixy>0</ixy>
            <ixz>0</ixz>
            <iyy>0.002646</iyy>
            <iyz>0</iyz>
            <izz>0.005292</izz>
          </inertia>
          <pose>0 0 0 0 -0 0</pose>
        </inertial>
        <visual name='visual'>
          <geometry>
            <mesh>
              <uri>model://khepera_IV/files/Empty_robot.dae</uri>
              <scale>1 1 1</scale>
            </mesh>
          </geometry>
        </visual>
        <collision name='collision'>
          <geometry>
            <mesh>
              <uri>model://khepera_IV/files/Empty_robot.dae</uri>
              <scale>1 1 1</scale>
            </mesh>
          </geometry>
          <max_contacts>10</max_contacts>
          <surface>
            <contact>
              <ode/>
            </contact>
            <bounce/>
            <friction>
              <torsional>
                <ode/>
              </torsional>
              <ode/>
            </friction>
          </surface>
        </collision>
        <sensor name='range0' type='ray'>
          <always_on>1</always_on>
          <visualize>0</visualize>
          <update_rate>30</update_rate>
          <pose>0 0.0645 0.045 0 -0 1.5707</pose>
          <ray>
            <scan>
              <horizontal>
                <samples>20</samples>
                <resolution>1</resolution>
                <min_angle>-0.5235</min_angle>
                <max_angle>0.5235</max_angle>
              </horizontal>
              <vertical>
                <samples>1</samples>
                <min_angle>0</min_angle>
                <max_angle>0</max_angle>
              </vertical>
            </scan>
            <range>
              <min>0.25</min>
              <max>2.5</max>
              <resolution>0.02</resolution>
            </range>
            <noise>
              <type>gaussian</type>
              <mean>0</mean>
              <stddev>0.01</stddev>
            </noise>
          </ray>
          <plugin name='range0' filename='libgazebo_ros_ray_sensor.so'>
            <ros>
              <remapping>~/out:=range0</remapping>
            </ros>
            <radiation_type>ultrasound</radiation_type>
            <output_type>sensor_msgs/Range</output_type>
          </plugin>
        </sensor>
        <sensor name='range1' type='ray'>
          <always_on>1</always_on>
          <visualize>0</visualize>
          <update_rate>30</update_rate>
          <pose>0.04561 0.04561 0.045 0 -0 0.7853</pose>
          <ray>
            <scan>
              <horizontal>
                <samples>20</samples>
                <resolution>1</resolution>
                <min_angle>-0.5235</min_angle>
                <max_angle>0.5235</max_angle>
              </horizontal>
              <vertical>
                <samples>1</samples>
                <min_angle>0</min_angle>
                <max_angle>0</max_angle>
              </vertical>
            </scan>
            <range>
              <min>0.25</min>
              <max>2.5</max>
              <resolution>0.02</resolution>
            </range>
            <noise>
              <type>gaussian</type>
              <mean>0</mean>
              <stddev>0.01</stddev>
            </noise>
          </ray>
          <plugin name='range1' filename='libgazebo_ros_ray_sensor.so'>
            <ros>
              <remapping>~/out:=range1</remapping>
            </ros>
            <radiation_type>ultrasound</radiation_type>
            <output_type>sensor_msgs/Range</output_type>
          </plugin>
        </sensor>
        <sensor name='range2' type='ray'>
          <always_on>1</always_on>
          <visualize>0</visualize>
          <update_rate>30</update_rate>
          <pose>0.0645 0 0.045 0 -0 0</pose>
          <ray>
            <scan>
              <horizontal>
                <samples>20</samples>
                <resolution>1</resolution>
                <min_angle>-0.5235</min_angle>
                <max_angle>0.5235</max_angle>
              </horizontal>
              <vertical>
                <samples>1</samples>
                <min_angle>0</min_angle>
                <max_angle>0</max_angle>
              </vertical>
            </scan>
            <range>
              <min>0.25</min>
              <max>2.5</max>
              <resolution>0.02</resolution>
            </range>
          </ray>
          <plugin name='range2' filename='libgazebo_ros_ray_sensor.so'>
            <ros>
              <remapping>~/out:=range2</remapping>
            </ros>
            <radiation_type>ultrasound</radiation_type>
            <output_type>sensor_msgs/Range</output_type>
          </plugin>
        </sensor>
        <sensor name='range3' type='ray'>
          <always_on>1</always_on>
          <visualize>0</visualize>
          <update_rate>30</update_rate>
          <pose>0.04561 -0.04561 0.045 0 0 -0.7853</pose>
          <ray>
            <scan>
              <horizontal>
                <samples>20</samples>
                <resolution>1</resolution>
                <min_angle>-0.5235</min_angle>
                <max_angle>0.5235</max_angle>
              </horizontal>
              <vertical>
                <samples>1</samples>
                <min_angle>0</min_angle>
                <max_angle>0</max_angle>
              </vertical>
            </scan>
            <range>
              <min>0.25</min>
              <max>2.5</max>
              <resolution>0.02</resolution>
            </range>
          </ray>
          <plugin name='range3' filename='libgazebo_ros_ray_sensor.so'>
            <ros>
              <remapping>~/out:=range3</remapping>
            </ros>
            <radiation_type>ultrasound</radiation_type>
            <output_type>sensor_msgs/Range</output_type>
          </plugin>
        </sensor>
        <sensor name='range4' type='ray'>
          <always_on>1</always_on>
          <visualize>0</visualize>
          <update_rate>30</update_rate>
          <pose>0 -0.0645 0.045 0 0 -1.5707</pose>
          <ray>
            <scan>
              <horizontal>
                <samples>20</samples>
                <resolution>1</resolution>
                <min_angle>-0.5235</min_angle>
                <max_angle>0.5235</max_angle>
              </horizontal>
              <vertical>
                <samples>1</samples>
                <min_angle>0</min_angle>
                <max_angle>0</max_angle>
              </vertical>
            </scan>
            <range>
              <min>0.25</min>
              <max>2.5</max>
              <resolution>0.02</resolution>
            </range>
          </ray>
          <plugin name='range4' filename='libgazebo_ros_ray_sensor.so'>
            <ros>
              <remapping>~/out:=range4</remapping>
            </ros>
            <radiation_type>ultrasound</radiation_type>
            <output_type>sensor_msgs/Range</output_type>
          </plugin>
        </sensor>
        <sensor name='ir00' type='gpu_ray'>
          <always_on>1</always_on>
          <visualize>0</visualize>
          <update_rate>30</update_rate>
          <pose>-0.04978 0.04978 0.01547 0 -0 2.3562</pose>
          <ray>
            <scan>
              <horizontal>
                <samples>20</samples>
                <resolution>1</resolution>
                <min_angle>-0.5235</min_angle>
                <max_angle>0.5235</max_angle>
              </horizontal>
              <vertical>
                <samples>1</samples>
                <min_angle>0</min_angle>
                <max_angle>0</max_angle>
              </vertical>
            </scan>
            <range>
              <min>0.002</min>
              <max>0.25</max>
              <resolution>0.02</resolution>
            </range>
          </ray>
          <plugin name='ir00' filename='libgazebo_ros_ray_sensor.so'>
            <ros>
              <remapping>~/out:=ir00</remapping>
            </ros>
            <radiation_type>infrared</radiation_type>
            <output_type>sensor_msgs/Range</output_type>
          </plugin>
        </sensor>
        <sensor name='ir01' type='gpu_ray'>
          <always_on>1</always_on>
          <visualize>0</visualize>
          <update_rate>30</update_rate>
          <pose>-0 0.0704 0.01547 0 -0 1.5708</pose>
          <ray>
            <scan>
              <horizontal>
                <samples>20</samples>
                <resolution>1</resolution>
                <min_angle>-0.5235</min_angle>
                <max_angle>0.5235</max_angle>
              </horizontal>
              <vertical>
                <samples>1</samples>
                <min_angle>0</min_angle>
                <max_angle>0</max_angle>
              </vertical>
            </scan>
            <range>
              <min>0.002</min>
              <max>0.25</max>
              <resolution>0.02</resolution>
            </range>
          </ray>
          <plugin name='ir01' filename='libgazebo_ros_ray_sensor.so'>
            <ros>
              <remapping>~/out:=ir01</remapping>
            </ros>
            <radiation_type>infrared</radiation_type>
            <output_type>sensor_msgs/Range</output_type>
          </plugin>
        </sensor>
        <sensor name='ir02' type='gpu_ray'>
          <always_on>1</always_on>
          <visualize>0</visualize>
          <update_rate>30</update_rate>
          <pose>0.04978 0.04978 0.01547 0 -0 0.7854</pose>
          <ray>
            <scan>
              <horizontal>
                <samples>20</samples>
                <resolution>1</resolution>
                <min_angle>-0.5235</min_angle>
                <max_angle>0.5235</max_angle>
              </horizontal>
              <vertical>
                <samples>1</samples>
                <min_angle>0</min_angle>
                <max_angle>0</max_angle>
              </vertical>
            </scan>
            <range>
              <min>0.002</min>
              <max>0.25</max>
              <resolution>0.02</resolution>
            </range>
          </ray>
          <plugin name='ir02' filename='libgazebo_ros_ray_sensor.so'>
            <ros>
              <remapping>~/out:=ir02</remapping>
            </ros>
            <radiation_type>infrared</radiation_type>
            <output_type>sensor_msgs/Range</output_type>
          </plugin>
        </sensor>
        <sensor name='ir03' type='gpu_ray'>
          <always_on>1</always_on>
          <visualize>0</visualize>
          <update_rate>30</update_rate>
          <pose>0.0704 0 0.01547 0 -0 0</pose>
          <ray>
            <scan>
              <horizontal>
                <samples>20</samples>
                <resolution>1</resolution>
                <min_angle>-0.5235</min_angle>
                <max_angle>0.5235</max_angle>
              </horizontal>
              <vertical>
                <samples>1</samples>
                <min_angle>0</min_angle>
                <max_angle>0</max_angle>
              </vertical>
            </scan>
            <range>
              <min>0.002</min>
              <max>0.25</max>
              <resolution>0.02</resolution>
            </range>
          </ray>
          <plugin name='ir03' filename='libgazebo_ros_ray_sensor.so'>
            <ros>
              <remapping>~/out:=ir03</remapping>
            </ros>
            <radiation_type>infrared</radiation_type>
            <output_type>sensor_msgs/Range</output_type>
          </plugin>
        </sensor>
        <sensor name='ir04' type='gpu_ray'>
          <always_on>1</always_on>
          <visualize>0</visualize>
          <update_rate>30</update_rate>
          <pose>0.04978 -0.04978 0.01547 0 0 -0.7854</pose>
          <ray>
            <scan>
              <horizontal>
                <samples>20</samples>
                <resolution>1</resolution>
                <min_angle>-0.5235</min_angle>
                <max_angle>0.5235</max_angle>
              </horizontal>
              <vertical>
                <samples>1</samples>
                <min_angle>0</min_angle>
                <max_angle>0</max_angle>
              </vertical>
            </scan>
            <range>
              <min>0.002</min>
              <max>0.25</max>
              <resolution>0.02</resolution>
            </range>
          </ray>
          <plugin name='ir04' filename='libgazebo_ros_ray_sensor.so'>
            <ros>
              <remapping>~/out:=ir04</remapping>
            </ros>
            <radiation_type>infrared</radiation_type>
            <output_type>sensor_msgs/Range</output_type>
          </plugin>
        </sensor>
        <sensor name='ir05' type='gpu_ray'>
          <always_on>1</always_on>
          <visualize>0</visualize>
          <update_rate>30</update_rate>
          <pose>-0 -0.0704 0.01547 0 0 -1.5708</pose>
          <ray>
            <scan>
              <horizontal>
                <samples>20</samples>
                <resolution>1</resolution>
                <min_angle>-0.5235</min_angle>
                <max_angle>0.5235</max_angle>
              </horizontal>
              <vertical>
                <samples>1</samples>
                <min_angle>0</min_angle>
                <max_angle>0</max_angle>
              </vertical>
            </scan>
            <range>
              <min>0.002</min>
              <max>0.25</max>
              <resolution>0.02</resolution>
            </range>
          </ray>
          <plugin name='ir05' filename='libgazebo_ros_ray_sensor.so'>
            <ros>
              <remapping>~/out:=ir05</remapping>
            </ros>
            <radiation_type>infrared</radiation_type>
            <output_type>sensor_msgs/Range</output_type>
          </plugin>
        </sensor>
        <sensor name='ir06' type='gpu_ray'>
          <always_on>1</always_on>
          <visualize>0</visualize>
          <update_rate>30</update_rate>
          <pose>-0.04978 -0.04978 0.01547 0 0 -2.3562</pose>
          <ray>
            <scan>
              <horizontal>
                <samples>20</samples>
                <resolution>1</resolution>
                <min_angle>-0.5235</min_angle>
                <max_angle>0.5235</max_angle>
              </horizontal>
              <vertical>
                <samples>1</samples>
                <min_angle>0</min_angle>
                <max_angle>0</max_angle>
              </vertical>
            </scan>
            <range>
              <min>0.002</min>
              <max>0.25</max>
              <resolution>0.02</resolution>
            </range>
          </ray>
          <plugin name='ir06' filename='libgazebo_ros_ray_sensor.so'>
            <ros>
              <remapping>~/out:=ir06</remapping>
            </ros>
            <radiation_type>infrared</radiation_type>
            <output_type>sensor_msgs/Range</output_type>
          </plugin>
        </sensor>
        <sensor name='ir07' type='gpu_ray'>
          <always_on>1</always_on>
          <visualize>0</visualize>
          <update_rate>30</update_rate>
          <pose>-0.0704 -0 0.01547 0 -0 3.14159</pose>
          <ray>
            <scan>
              <horizontal>
                <samples>20</samples>
                <resolution>1</resolution>
                <min_angle>-0.5235</min_angle>
                <max_angle>0.5235</max_angle>
              </horizontal>
              <vertical>
                <samples>1</samples>
                <min_angle>0</min_angle>
                <max_angle>0</max_angle>
              </vertical>
            </scan>
            <range>
              <min>0.002</min>
              <max>0.25</max>
              <resolution>0.02</resolution>
            </range>
          </ray>
          <plugin name='ir07' filename='libgazebo_ros_ray_sensor.so'>
            <ros>
              <remapping>~/out:=ir07</remapping>
            </ros>
            <radiation_type>infrared</radiation_type>
            <output_type>sensor_msgs/Range</output_type>
          </plugin>
        </sensor>
        <sensor name='ir08' type='gpu_ray'>
          <always_on>1</always_on>
          <visualize>0</visualize>
          <update_rate>30</update_rate>
          <pose>0.019618 0.059522 0.0057 -3.14159 1.57079 1.57089</pose>
          <ray>
            <scan>
              <horizontal>
                <samples>20</samples>
                <resolution>1</resolution>
                <min_angle>-0.5235</min_angle>
                <max_angle>0.5235</max_angle>
              </horizontal>
              <vertical>
                <samples>1</samples>
                <min_angle>0</min_angle>
                <max_angle>0</max_angle>
              </vertical>
            </scan>
            <range>
              <min>0.002</min>
              <max>0.25</max>
              <resolution>0.02</resolution>
            </range>
          </ray>
          <plugin name='ir08' filename='libgazebo_ros_ray_sensor.so'>
            <ros>
              <remapping>~/out:=ir08</remapping>
            </ros>
            <radiation_type>infrared</radiation_type>
            <output_type>sensor_msgs/Range</output_type>
          </plugin>
        </sensor>
        <sensor name='ir09' type='gpu_ray'>
          <always_on>1</always_on>
          <visualize>0</visualize>
          <update_rate>30</update_rate>
          <pose>0.062921 0.01 0.0057 3.14159 1.57079 3.14159</pose>
          <ray>
            <scan>
              <horizontal>
                <samples>20</samples>
                <resolution>1</resolution>
                <min_angle>-0.5235</min_angle>
                <max_angle>0.5235</max_angle>
              </horizontal>
              <vertical>
                <samples>1</samples>
                <min_angle>0</min_angle>
                <max_angle>0</max_angle>
              </vertical>
            </scan>
            <range>
              <min>0.002</min>
              <max>0.25</max>
              <resolution>0.02</resolution>
            </range>
          </ray>
          <plugin name='ir09' filename='libgazebo_ros_ray_sensor.so'>
            <ros>
              <remapping>~/out:=ir09</remapping>
            </ros>
            <radiation_type>infrared</radiation_type>
            <output_type>sensor_msgs/Range</output_type>
          </plugin>
        </sensor>
        <sensor name='ir10' type='gpu_ray'>
          <always_on>1</always_on>
          <visualize>0</visualize>
          <update_rate>30</update_rate>
          <pose>0.062921 -0.01 0.0057 3.14159 1.57079 3.14159</pose>
          <ray>
            <scan>
              <horizontal>
                <samples>20</samples>
                <resolution>1</resolution>
                <min_angle>-0.5235</min_angle>
                <max_angle>0.5235</max_angle>
              </horizontal>
              <vertical>
                <samples>1</samples>
                <min_angle>0</min_angle>
                <max_angle>0</max_angle>
              </vertical>
            </scan>
            <range>
              <min>0.002</min>
              <max>0.25</max>
              <resolution>0.02</resolution>
            </range>
          </ray>
          <plugin name='ir10' filename='libgazebo_ros_ray_sensor.so'>
            <ros>
              <remapping>~/out:=ir10</remapping>
            </ros>
            <radiation_type>infrared</radiation_type>
            <output_type>sensor_msgs/Range</output_type>
          </plugin>
        </sensor>
        <sensor name='ir11' type='gpu_ray'>
          <always_on>1</always_on>
          <visualize>0</visualize>
          <update_rate>30</update_rate>
          <pose>0.019618 -0.059522 0.0057 -3.14159 1.57079 1.57089</pose>
          <ray>
            <scan>
              <horizontal>
                <samples>20</samples>
                <resolution>1</resolution>
                <min_angle>-0.5235</min_angle>
                <max_angle>0.5235</max_angle>
              </horizontal>
              <vertical>
                <samples>1</samples>
                <min_angle>0</min_angle>
                <max_angle>0</max_angle>
              </vertical>
            </scan>
            <range>
              <min>0.002</min>
              <max>0.25</max>
              <resolution>0.02</resolution>
            </range>
          </ray>
          <plugin name='ir11' filename='libgazebo_ros_ray_sensor.so'>
            <ros>
              <remapping>~/out:=ir11</remapping>
            </ros>
            <radiation_type>infrared</radiation_type>
            <output_type>sensor_msgs/Range</output_type>
          </plugin>
        </sensor>
        <sensor name='imu_sensor' type='imu'>
          <pose>0 0 0.04 0 -0 0</pose>
          <always_on>1</always_on>
          <update_rate>30</update_rate>
          <plugin name='imu_plugin' filename='libgazebo_ros_imu_sensor.so'>
            <ros>
              <remapping>~/out:=imu/data</remapping>
            </ros>
          </plugin>
          <imu/>
        </sensor>
        <sensor name='camera' type='camera'>
          <pose>0.0645 0 0.025 0 -0 0</pose>
          <update_rate>30</update_rate>
          <camera name='head'>
            <horizontal_fov>0.96</horizontal_fov>
            <image>
              <width>960</width>
              <height>720</height>
              <format>R8G8B8</format>
            </image>
            <clip>
              <near>0.1</near>
              <far>300</far>
            </clip>
            <noise>
              <type>gaussian</type>
              <mean>0</mean>
              <stddev>0.007</stddev>
            </noise>
          </camera>
          <plugin name='camera' filename='libgazebo_ros_camera.so'>
            <alwaysOn>1</alwaysOn>
            <updateRate>0.0</updateRate>
            <cameraName>this_is_ignored</cameraName>
            <imageTopicName>image_raw</imageTopicName>
            <cameraInfoTopicName>camera_info</cameraInfoTopicName>
            <frameName>chassis</frameName>
            <hackBaseline>0.07</hackBaseline>
            <distortionK1>0.0</distortionK1>
            <distortionK2>0.0</distortionK2>
            <distortionK3>0.0</distortionK3>
            <distortionT1>0.0</distortionT1>
            <distortionT2>0.0</distortionT2>
          </plugin>
        </sensor>
        <self_collide>0</self_collide>
        <enable_wind>0</enable_wind>
        <kinematic>0</kinematic>
      </link>
      <link name='left_wheel'>
        <pose>0 0.0527 0.021 -1.5707 0 0</pose>
        <inertial>
          <mass>0.02</mass>
          <inertia>
            <ixx>3e-06</ixx>
            <ixy>0</ixy>
            <ixz>0</ixz>
            <iyy>3e-06</iyy>
            <iyz>0</iyz>
            <izz>3e-06</izz>
          </inertia>
          <pose>0 0 0 0 -0 0</pose>
        </inertial>
        <visual name='visual'>
          <geometry>
            <mesh>
              <uri>model://khepera_IV/files/wheel.dae</uri>
              <scale>1 1 1</scale>
            </mesh>
          </geometry>
        </visual>
        <collision name='collision'>
          <geometry>
            <mesh>
              <uri>model://khepera_IV/files/wheel.dae</uri>
              <scale>1 1 1</scale>
            </mesh>
          </geometry>
          <surface>
            <friction>
              <ode>
                <mu>1</mu>
                <mu2>1</mu2>
                <slip1>0</slip1>
                <slip2>0</slip2>
              </ode>
              <torsional>
                <ode/>
              </torsional>
            </friction>
            <contact>
              <ode>
                <soft_cfm>0</soft_cfm>
                <soft_erp>0.2</soft_erp>
                <kp>1e+13</kp>
                <kd>1</kd>
                <max_vel>0.01</max_vel>
                <min_depth>0.01</min_depth>
              </ode>
            </contact>
            <bounce/>
          </surface>
          <max_contacts>10</max_contacts>
        </collision>
        <self_collide>0</self_collide>
        <enable_wind>0</enable_wind>
        <kinematic>0</kinematic>
      </link>
      <link name='right_wheel'>
        <pose>0 -0.0527 0.021 -1.5707 0 0</pose>
        <inertial>
          <mass>0.02</mass>
          <inertia>
            <ixx>3e-06</ixx>
            <ixy>0</ixy>
            <ixz>0</ixz>
            <iyy>3e-06</iyy>
            <iyz>0</iyz>
            <izz>3e-06</izz>
          </inertia>
          <pose>0 0 0 0 -0 0</pose>
        </inertial>
        <visual name='visual'>
          <geometry>
            <mesh>
              <uri>model://khepera_IV/files/wheel.dae</uri>
              <scale>1 1 1</scale>
            </mesh>
          </geometry>
        </visual>
        <collision name='collision'>
          <geometry>
            <mesh>
              <uri>model://khepera_IV/files/wheel.dae</uri>
              <scale>1 1 1</scale>
            </mesh>
          </geometry>
          <surface>
            <friction>
              <ode>
                <mu>1</mu>
                <mu2>1</mu2>
                <slip1>0</slip1>
                <slip2>0</slip2>
              </ode>
              <torsional>
                <ode/>
              </torsional>
            </friction>
            <contact>
              <ode>
                <soft_cfm>0</soft_cfm>
                <soft_erp>0.2</soft_erp>
                <kp>1e+13</kp>
                <kd>1</kd>
                <max_vel>0.01</max_vel>
                <min_depth>0.01</min_depth>
              </ode>
            </contact>
            <bounce/>
          </surface>
          <max_contacts>10</max_contacts>
        </collision>
        <self_collide>0</self_collide>
        <enable_wind>0</enable_wind>
        <kinematic>0</kinematic>
      </link>
      <link name='front_caster'>
        <pose>0.05 0 0.006614 0 -0 0</pose>
        <visual name='visual'>
          <geometry>
            <mesh>
              <uri>model://khepera_IV/files/caster.dae</uri>
              <scale>1 1 1</scale>
            </mesh>
          </geometry>
        </visual>
        <collision name='collision'>
          <geometry>
            <mesh>
              <uri>model://khepera_IV/files/caster.dae</uri>
              <scale>1 1 1</scale>
            </mesh>
          </geometry>
          <max_contacts>10</max_contacts>
          <surface>
            <contact>
              <ode/>
            </contact>
            <bounce/>
            <friction>
              <torsional>
                <ode/>
              </torsional>
              <ode/>
            </friction>
          </surface>
        </collision>
        <self_collide>0</self_collide>
        <inertial>
          <pose>0 0 0 0 -0 0</pose>
          <inertia>
            <ixx>1</ixx>
            <ixy>0</ixy>
            <ixz>0</ixz>
            <iyy>1</iyy>
            <iyz>0</iyz>
            <izz>1</izz>
          </inertia>
          <mass>1</mass>
        </inertial>
        <enable_wind>0</enable_wind>
        <kinematic>0</kinematic>
      </link>
      <link name='back_caster'>
        <pose>-0.05 0 0.006614 0 -0 0</pose>
        <visual name='visual'>
          <geometry>
            <mesh>
              <uri>model://khepera_IV/files/caster.dae</uri>
              <scale>1 1 1</scale>
            </mesh>
          </geometry>
        </visual>
        <collision name='collision'>
          <geometry>
            <mesh>
              <uri>model://khepera_IV/files/caster.dae</uri>
              <scale>1 1 1</scale>
            </mesh>
          </geometry>
          <max_contacts>10</max_contacts>
          <surface>
            <contact>
              <ode/>
            </contact>
            <bounce/>
            <friction>
              <torsional>
                <ode/>
              </torsional>
              <ode/>
            </friction>
          </surface>
        </collision>
        <self_collide>0</self_collide>
        <inertial>
          <pose>0 0 0 0 -0 0</pose>
          <inertia>
            <ixx>1</ixx>
            <ixy>0</ixy>
            <ixz>0</ixz>
            <iyy>1</iyy>
            <iyz>0</iyz>
            <izz>1</izz>
          </inertia>
          <mass>1</mass>
        </inertial>
        <enable_wind>0</enable_wind>
        <kinematic>0</kinematic>
      </link>
      <joint name='left_wheel_joint' type='revolute'>
        <parent>chassis</parent>
        <child>left_wheel</child>
        <axis>
          <xyz>0 0 1</xyz>
          <limit>
            <lower>-1.79769e+308</lower>
            <upper>1.79769e+308</upper>
          </limit>
          <dynamics>
            <spring_reference>0</spring_reference>
            <spring_stiffness>0</spring_stiffness>
          </dynamics>
        </axis>
      </joint>
      <joint name='right_wheel_joint' type='revolute'>
        <parent>chassis</parent>
        <child>right_wheel</child>
        <axis>
          <xyz>0 0 1</xyz>
          <limit>
            <lower>-1.79769e+308</lower>
            <upper>1.79769e+308</upper>
          </limit>
          <dynamics>
            <spring_reference>0</spring_reference>
            <spring_stiffness>0</spring_stiffness>
          </dynamics>
        </axis>
      </joint>
      <joint name='front_caster_wheel' type='ball'>
        <parent>chassis</parent>
        <child>front_caster</child>
      </joint>
      <joint name='back_caster_wheel' type='ball'>
        <parent>chassis</parent>
        <child>back_caster</child>
      </joint>
      <plugin name='diff_drive' filename='libgazebo_ros_diff_drive.so'>
        <ros>
          <remapping>odom:=odom</remapping>
        </ros>
        <left_joint>left_wheel_joint</left_joint>
        <right_joint>right_wheel_joint</right_joint>
        <wheel_separation>0.1054</wheel_separation>
        <wheel_diameter>0.021</wheel_diameter>
        <max_wheel_torque>20</max_wheel_torque>
        <max_wheel_acceleration>1.0</max_wheel_acceleration>
        <publish_odom>1</publish_odom>
        <publish_odom_tf>1</publish_odom_tf>
        <publish_wheel_tf>1</publish_wheel_tf>
        <odometry_frame>odom</odometry_frame>
        <robot_base_frame>chassis</robot_base_frame>
      </plugin>
      <plugin name='ground_truth' filename='libgazebo_ros_p3d.so'>
        <ros>
          <remapping>odom:=ground_truth</remapping>
        </ros>
        <frame_name>map</frame_name>
        <body_name>chassis</body_name>
        <update_rate>100.0</update_rate>
        <gaussian_noise>0.01</gaussian_noise>
      </plugin>
    </model>
  </world>
</sdf>
