<?xml version="1.0"?>

<!-- Body coordinates are: x forward, y left, z up; rotation is: roll right, pitch forward, yaw left -->
<!-- See http://www.ros.org/reps/rep-0103.html -->
<!-- model://khepera_IV :: package://uned_khepera_description/meshes -->

<robot name="khepera${suffix}">

    <!-- Base link -->
    <link name="base_link${suffix}">
        <inertial>
            <mass value="0.5"/>
            <inertia ixx="0.0007365" ixy="0" ixz="0" iyy="0.0007365" iyz="0" izz="0.001239"/>
        </inertial>
        <visual>
            <geometry>
                <mesh filename="model://khepera_IV/files/Empty_robot.dae" scale="1.0 1.0 1.0"/>
            </geometry>
        </visual>
        
        <collision name="collision">
            <geometry>
                <mesh filename="model://khepera_IV/files/Empty_robot.dae" scale="1.0 1.0 1.0"/>
            </geometry>
        </collision>

    </link>

    <!-- Wheel Left -->
    <link name="left_wheel${suffix}">    
        <inertial>
            <mass value="0.02"/>
            <origin rpy="-1.57070 0 0" xyz="0 0 0"/>
            <inertia ixx="0.000003" ixy="0" ixz="0" iyy="0.000003" iyz="0" izz="0.000003"/>
        </inertial> 
        <visual>
            <origin rpy="-1.57070 0 0" xyz="0 0 0"/>
            <geometry>
                <mesh filename="model://khepera_IV/files/wheel.dae" scale="1.0 1.0 1.0"/>
            </geometry>
        </visual>
        <collision name='collision'>
            <origin rpy="-1.57070 0 0" xyz="0 0 0"/>
            <geometry>
                <mesh filename="model://khepera_IV/files/wheel.dae" scale="1.0 1.0 1.0"/>
            </geometry>
        </collision>
    </link>
    <joint name="left_wheel_joint${suffix}" type="continuous">
        <origin rpy="0 0 0" xyz="0 0.0527 0.021"/>
        <child link="left_wheel${suffix}"/>
        <parent link="base_link${suffix}"/>
        <axis rpy="0 0 0" xyz="0 1 0"/>
        <limit effort="10000" velocity="1000"/>
        <joint_properties damping="1.0" friction="1.0"/>
    </joint>
    
    <!-- Wheel Right -->
    <link name="right_wheel${suffix}">    
        <inertial>
            <mass value="0.02"/>
            <origin rpy="-1.57070 0 0" xyz="0 0 0"/>
            <inertia ixx="0.000003" ixy="0" ixz="0" iyy="0.000003" iyz="0" izz="0.000003"/>
        </inertial> 
        <visual>
            <origin rpy="-1.57070 0 0" xyz="0 0 0"/>
            <geometry>
                <mesh filename="model://khepera_IV/files/wheel.dae" scale="1.0 1.0 1.0"/>
            </geometry>
        </visual>
        <collision name='collision'>
            <origin rpy="-1.57070 0 0" xyz="0 0 0"/>
            <geometry>
                <mesh filename="model://khepera_IV/files/wheel.dae" scale="1.0 1.0 1.0"/>
            </geometry>
        </collision>
    </link>
    <joint name="right_wheel_joint${suffix}" type="continuous">
        <origin rpy="0 0 0" xyz="0 -0.0527 0.021"/>
        <child link="right_wheel${suffix}"/>
        <parent link="base_link${suffix}"/>
        <axis rpy="0 0 0" xyz="0 1 0"/>
        <limit effort="10000" velocity="1000"/>
        <joint_properties damping="1.0" friction="1.0"/>
    </joint>

    <!-- Front Caster -->
    <link name="front_caster${suffix}">    
        <visual>
            <origin rpy="0 0 0" xyz="0.05 0 0.006614"/>
            <geometry>
                <mesh filename="model://khepera_IV/files/caster.dae" scale="1.0 1.0 1.0"/>
            </geometry>
        </visual>
        <collision name='collision'>
            <origin rpy="0 0 0" xyz="0.05 0 0.006614"/>
            <geometry>
                <mesh filename="model://khepera_IV/files/caster.dae" scale="1.0 1.0 1.0"/>
            </geometry>
        </collision>
    </link>
    <joint name="front_caster_joint${suffix}" type="fixed">
        <child link="front_caster${suffix}"/>
        <parent link="base_link${suffix}"/>
        <joint_properties damping="0.0" friction="0.001"/>
    </joint>

    <!-- Back Caster -->
    <link name="back_caster${suffix}">    
        <visual>
            <origin rpy="0 0 0" xyz="-0.05 0 0.006614"/>
            <geometry>
                <mesh filename="model://khepera_IV/files/caster.dae" scale="1.0 1.0 1.0"/>
            </geometry>
        </visual>
        <collision name='collision'>
            <origin rpy="0 0 0" xyz="-0.05 0 0.006614"/>
            <geometry>
                <mesh filename="model://khepera_IV/files/caster.dae" scale="1.0 1.0 1.0"/>
            </geometry>
        </collision>
    </link>
    <joint name="back_caster_joint${suffix}" type="fixed">
        <child link="back_caster${suffix}"/>
        <parent link="base_link${suffix}"/>
        <joint_properties damping="0.0" friction="0.001"/>
    </joint>

    <gazebo>
        <plugin name="ground_truth" filename="libgazebo_ros_p3d.so">
            <ros>
                <namespace>khepera${suffix}</namespace>
                <remapping>odom:=ground_truth</remapping>
            </ros>
            <frame_name>map</frame_name>
            <body_name>base_link${suffix}</body_name>
            <update_rate>100.0</update_rate>
            <gaussian_noise>0.01</gaussian_noise>
        </plugin>
    </gazebo>

    <gazebo>
        <plugin name='diff_drive' filename='libgazebo_ros_diff_drive.so'>
            <ros>
                <namespace>khepera${suffix}</namespace>
                <remapping>odom:=odom</remapping>
            </ros>

            <!-- wheels -->
            <left_joint>left_wheel_joint${suffix}</left_joint>
            <right_joint>right_wheel_joint${suffix}</right_joint>
            <!-- kinematics -->
            <wheel_separation>0.1054</wheel_separation>
            <wheel_diameter>0.021</wheel_diameter>
            <!-- limits -->
            <max_wheel_torque>20</max_wheel_torque>
            <max_wheel_acceleration>1.0</max_wheel_acceleration>
            <!-- output -->
            <publish_odom>true</publish_odom>
            <publish_odom_tf>true</publish_odom_tf>
            <publish_wheel_tf>true</publish_wheel_tf>


            <odometry_frame>odom</odometry_frame>
            <robot_base_frame>base_link${suffix}</robot_base_frame>
        </plugin>
    </gazebo>
 
</robot>